Workbook

Sheet backup Portugal
A1: Empresa | B1: País | C1: Área | F1: Modelo SaaS ou tecnologia escalável com componente recorrente | J1: A seleção inicial das empresas foi realizada a partir de bases públicas amplamente utilizadas no mapeamento de ecossistemas de inovação, incluindo relatórios do Distrito (Brasil), Dealroom (Portugal), Startup Portugal e LinkedIn Company Directory.
A2: OutSystems | B2: Portugal | C2: DevTools / Low-Code | F2: Atuação predominante B2B
A3: Talkdesk | B3: Portugal | C3: CX / Contact Center | F3: Entre 20 e 500 colaboradores
A4: Feedzai | B4: Portugal | C4: Fintech / Fraud | F4: Pelo menos uma rodada de funding identificável
A5: Remote | B5: Portugal | C5: HRTech / Global Payroll | F5: Dados públicos disponíveis via LinkedIn e Crunchbase
A6: Sword Health | B6: Portugal | C6: HealthTech
A7: Unbabel | B7: Portugal | C7: AI / Language Tech | F7: Dealroom
A8: Defined.ai | B8: Portugal | C8: AI / Data | F8: Startup Portugal
A9: Infraspeak | B9: Portugal | C9: Facility Management SaaS | F9: Web Summit
A10: Codacy | B10: Portugal | C10: DevTools | F10: Distrito
A11: Jscrambler | B11: Portugal | C11: Cybersecurity
A12: Uniplaces | B12: Portugal | C12: PropTech
A13: Casafari | B13: Portugal | C13: PropTech / Data
A14: StudentFinance | B14: Portugal | C14: Fintech / EdFinance
A15: Probely | B15: Portugal | C15: Cybersecurity
A16: TonicApp | B16: Portugal | C16: HealthTech
A17: Rows | B17: Portugal | C17: Productivity SaaS
A18: Veniam | B18: Portugal | C18: Networking / Infra
A19: Blip | B19: Portugal | C19: Conversational Commerce
A20: Critical Software | B20: Portugal | C20: Enterprise Software
A21: Glintt | B21: Portugal | C21: HealthTech
A22: 360imprimir | B22: Portugal | C22: B2B Commerce SaaS
... A81: Clicksign | B81: Brazil | C81: Digital Signature

Sheet backup Brasil
A1: Organização | B1: Tipo de Finan. | C1: Funct. | D1: Indústrias (Resumo) | E1: Localização | F1: País | G1: CB Rank | H1: Data Últ. Finan. | I1: Status | J1: Total Captado | K1: Último Aporte | L1: Growth
A2: Bravium | B2: Venture | C2: 251-500 | D2: B2B, Loyalty, Analytics | E2: São Paulo | F2: Brasil | G2: 49895 | H2: 44817 | I2: — | J2: R$ 100M | K2: R$ 100M | L2: Low
A3: Moss.Earth | B3: Series A | C3: 51-100 | D3: Enviromental, Eng. | E3: São Paulo | F3: Brasil | G3: 50099 | H3: 44592 | I3: Early Stage Venture | J3: $13.4M | K3: $ 10M | L3: Low
A4: Doris | B4: Seed | C4: 11-50 | D4: Fashion, GenAI | E4: São Paulo | F4: Brasil | G4: 50105 | H4: 43983 | I4: Seed | J4: $10M | K4: $ 10M | L4: Low
A5: Loft | B5: Venture | C5: 1001-5k | D5: PropTech, FinTech | E5: São Paulo | F5: Brasil | G5: 50259 | H5: 45146 | I5: — | J5: $888M | K5: $ 100M | L5: Medium
A6: Yuca | B6: Series A | C6: 101-250 | D6: PropTech, Rental | E6: São Paulo | F6: Brasil | G6: 50484 | H6: 44369 | I6: Early Stage Venture | J6: $14.7M | K6: $ 10M | L6: Low
A7: Fintalk AI | B7: Venture | C7: 51-100 | D7: AI, Sales Auto. | E7: São Paulo | F7: Brasil | G7: 50570 | H7: 45776 | I7: — | J7: $ 3M | K7: R$ 6M | L7: Low
A8: Salú | B8: Seed | C8: 101-250 | D8: Health Care, SaaS | E8: São Paulo | F8: Brasil | G8: 50983 | H8: 44649 | I8: Seed | J8: R$ 12M | K8: R$ 12M | L8: Low
A9: Foxbit | B9: Series A | C9: 11-50 | D9: Crypto, FinTech | E9: São Paulo | F9: Brasil | G9: 50993 | H9: 44614 | I9: Early Stage Venture | J9: $21.1M | K9: $ 21M | L9: Low
A10: IBBX | B10: Venture | C10: 51-100 | D10: IoT, Energy Mgmt | E10: Capivari | F10: Brasil | G10: 51024 | H10: 44721 | I10: — | J10: $5M | K10: $ 5M | L10: Low
A11: Nomo | B11: Seed | C11: 51-100 | D11: Telecom, IT | E11: São Paulo | F11: Brasil | G11: 51432 | H11: 44511 | I11: M&A | J11: R$ 14M | K11: R$ 14M | L11: High
A12: Turn2C | B12: Series A | C12: 51-100 | D12: AI, Finance | E12: São Paulo | F12: Brasil | G12: 51440 | H12: 45354 | I12: Early Stage Venture | J12: R$ 33.5M | K12: R$ 25M | L12: High
A13: Clubbi | B13: Series A | C13: 101-250 | D13: B2B, RetailTech | E13: Rio de Jan. | F13: Brasil | G13: 51732 | H13: 44713 | I13: Early Stage Venture | J13: $17M | K13: $ 12M | L13: Low
... A39: unico IDtech | B39: Series D | C39: 501-1k | D39: Identity Mgmt | E39: São Paulo | F39: Brasil | G39: 55876 | H39: 44665 | I39: Late Stage Venture | J39: $336M | K39: $ 100M | L39: Low
A40: 3778 | B40: Venture | C40: 1001-5k | D40: HealthTech, Data | E40: Minas Gerais | F40: Brasil | G40: 56426 | H40: 44252 | I40: — | J40: R$ 200M | K40: R$ 200M | L40: Low
A41: Agilize | B41: Venture | C41: 101-250 | D41: Accounting, FinTech | E41: Salvador | F41: Brasil | G41: 56468 | H41: 45625 | I41: — | J41: $9M | K41: $ 9M | L41: High
A42: Neoenergia | B42: Post-IPO Debt | C42: 10k+ | D42: Renewable Energy | E42: Rio de Jan. | F42: Brasil | G42: 56547 | H42: 45839 | I42: IPO | J42: $ 735M | K42: € 300M | L42: Medium
A43: Kenlo | B43: Venture | C43: 101-250 | D43: PropTech, SaaS | E43: Campina | F43: Brasil | G43: 57140 | H43: 44417 | I43: — | J43: R$ 122M | K43: R$ 95M | L43: Low
A44: Vittude | B44: Series A | C44: 101-250 | D44: HealthTech, SaaS | E44: São Paulo | F44: Brasil | G44: 57486 | H44: 44635 | I44: Early Stage Venture | J44: $8.4M | K44: $ 7M | L44: Low
A45: SuaQuadra | B45: Seed | C45: 11-50 | D45: PropTech, Rental | E45: São Paulo | F45: Brasil | G45: 57496 | H45: 45104 | I45: Seed | J45: R$ 21M | K45: R$ 21M | L45: Low
A46: Gerdau | B46: Post-IPO Debt | C46: 10k+ | D46: Manufacturing, Steel | E46: São Paulo | F46: Brasil | G46: 57623 | H46: 45829 | I46: IPO | J46: R$ 566M | K46: R$ 566M | L46: Low
A47: Alinea Health | B47: Venture | C47: 11-50 | D47: HealthTech, Corp. | E47: São Paulo | F47: Brasil | G47: 57686 | H47: 44636 | I47: — | J47: R$ 21.3M | K47: R$ 20M | L47: Low
A48: Hi Platform | B48: Series A | C48: 101-250 | D48: AI, Customer Svc | E48: São Paulo | F48: Brasil | G48: 57780 | H48: 44469 | I48: Early Stage Venture | J48: R$ 35M | K48: R$ 35M | L48: Low
A49: FOOD TO SAVE | B49: Seed | C49: 51-100 | D49: Waste Mgmt, Food | E49: São Paulo | F49: Brasil | G49: 58000 | H49: 45211 | I49: Seed | J49: $3.7M | K49: $ 3.1M | L49: High
A50: Truth & Tales | B50: Seed | C50: 11-50 | D50: EdTech, Gaming | E50: Florianópolis | F50: Brasil | G50: 58069 | H50: 43353 | I50: Seed | J50: R$ 1.2M | K50: R$ 1.2M | L50: Low
A51: Psyche Aero. | B51: Venture | C51: 101-250 | D51: Aerospace, AgTech | E51: S. J. Campos | F51: Brasil | G51: 58366 | H51: 45589 | I51: — | J51: R$ 34.2M | K51: R$ 17M | L51: Low

Sheet Dados
B1: Nome da empresa | C1: País | D1: Cidade | E1: Ano de fundação | F1: Total HC | G1: Crescimento HC 12 meses | H1: Funcionários engenharia | I1: Funcionários vendas | J1: Funcionários marketing | K1: Funcionários CS | L1: Funding (USD) | M1: Número de rodadas | N1: Ano de ultima rodada | O1: Status de funding | P1: Growth score (métrica do próprio cb) | Q1: Funding/HC | R1: Tech/Sales rate | S1: Fundação até ult rodada | T1: Seguidores linkedin | U1: TEM IA | V1: Tendencia aumento de quadro ult 12m
A2: Crunchbase | B2: x | C2: x | D2: x | F2: x | L2: x | N2: x | O2: x | P2: x | Q2: =L1/F1 -> #VALUE! | R2: =I1/H1 -> #VALUE! | S2: =N2-E2 -> #VALUE!
A3: Linkedin | E3: x | H3: proxy | I3: proxy | J3: proxy
B6: 659 | C6: Oct 2, 2025 | D6: Late Stage Ventur

Sheet  Dataset - Bruto
A1: Organização | B1: Tipo de Finan. | C1: Funct. | D1: Indústrias (Resumo) | E1: Localização | F1: País | G1: CB Rank | H1: Data Últ. Finan. | I1: Status | J1: Total Captado | K1: Último Aporte | L1: Growth | M1: Faixa de vidas | O1: Funct. | P1: Brasil | Q1: Portugal
A2: Jáchegou | B2: Seed | C2: 11-50 | D2: Delivery, E-Commerce | E2: Porto | F2: Portugal | G2: 164.97 | H2: 44896 | I2: Seed | J2: 150 | K2: 50 | L2: Low | M2: =VLOOKUP(C2,Apoio!A:B,2,0) -> 11-50 | O2: 11-50 | P2: =COUNTIFS($F:$F,P$1,$M:$M,$O2,A:A,"<>"&"Seed") -> 59 | Q2: =COUNTIFS($F:$F,Q$1,$M:$M,$O2,B:B,"<>"&"Seed") -> 47 | T2: Empresas de 11 - 1000 funcionários
A3: PharmAssistant | B3: Seed | C3: 11-50 | D3: Health Tech, Hardware | E3: Lisboa | F3: Portugal | G3: 610.511 | H3: 41877 | I3: Seed | J3: 50 | K3: 50 | L3: Low | M3: =VLOOKUP(C3,Apoio!A:B,2,0) -> 11-50 | O3: 51-100 | P3: =COUNTIFS($F:$F,P$1,$M:$M,$O3,A:A,"<>"&"Seed") -> 31 | Q3: =COUNTIFS($F:$F,Q$1,$M:$M,$O3,B:B,"<>"&"Seed") -> 13 | T3: Passaram da fase seed
A4: Bandora | B4: Venture | C4: 11-50 | D4: AI, Smart Building | E4: Porto | F4: Portugal | G4: 9.616 | H4: 45832 | I4: — | J4: €2,135,383 | K4: 100 | L4: Low | M4: =VLOOKUP(C4,Apoio!A:B,2,0) -> 11-50 | O4: 101-250 | P4: =COUNTIFS($F:$F,P$1,$M:$M,$O4,A:A,"<>"&"Seed") -> 39 | Q4: =COUNTIFS($F:$F,Q$1,$M:$M,$O4,B:B,"<>"&"Seed") -> 4
A5: Wakaru | B5: Seed | C5: 11-50 | D5: Cyber Security, Analytics | E5: Torres V. | F5: Portugal | G5: 138.709 | H5: 44222 | I5: Seed | J5: 100 | K5: 100 | L5: Low | M5: =VLOOKUP(C5,Apoio!A:B,2,0) -> 11-50 | O5: 251-500 | P5: =COUNTIFS($F:$F,P$1,$M:$M,$O5,A:A,"<>"&"Seed") -> 16 | Q5: =COUNTIFS($F:$F,Q$1,$M:$M,$O5,B:B,"<>"&"Seed") -> 3
A6: Avenidas | B6: Venture | C6: 51-100 | D6: Mobility, Transportation | E6: Lisboa | F6: Portugal | G6: 167.71 | H6: 45027 | I6: — | J6: 100 | K6: 100 | L6: High | M6: =VLOOKUP(C6,Apoio!A:B,2,0) -> 51-100 | O6: 501-1000 | P6: =COUNTIFS($F:$F,P$1,$M:$M,$O6,A:A,"<>"&"Seed") -> 15 | Q6: =COUNTIFS($F:$F,Q$1,$M:$M,$O6,B:B,"<>"&"Seed") -> 3
A7: Ubiwhere | B7: Seed | C7: 11-50 | D7: Smart Cities, Software | E7: Barrocas | F7: Portugal | G7: 172.334 | H7: 43132 | I7: Seed | J7: 100 | K7: 100 | L7: Low | M7: =VLOOKUP(C7,Apoio!A:B,2,0) -> 11-50 | O7: 1k-5k | P7: =COUNTIFS($F:$F,P$1,$M:$M,$O7) -> 10 | Q7: =COUNTIFS($F:$F,Q$1,$M:$M,$O7) -> 1
A8: AQVA MORE | B8: Seed | C8: 11-50 | D8: Water Purification, Mfg | E8: Oeiras | F8: Portugal | G8: 191.396 | H8: 44187 | I8: Seed | J8: 100 | K8: 100 | L8: Low | M8: =VLOOKUP(C8,Apoio!A:B,2,0) -> 11-50 | O8: 5k-10k | P8: =COUNTIFS($F:$F,P$1,$M:$M,$O8) -> 3 | Q8: =COUNTIFS($F:$F,Q$1,$M:$M,$O8) -> 0
A9: Cuckuu | B9: Seed | C9: 11-50 | D9: Social Alarm, Mobile Apps | E9: Lisboa | F9: Portugal | G9: 204.915 | H9: 42706 | I9: Seed | J9: $1,164,772 | K9: 100 | L9: — | M9: =VLOOKUP(C9,Apoio!A:B,2,0) -> 11-50 | O9: 10k+ | P9: =COUNTIFS($F:$F,P$1,$M:$M,$O9) -> 8 | Q9: =COUNTIFS($F:$F,Q$1,$M:$M,$O9) -> 2
A10: YouClap | B10: Seed | C10: 11-50 | D10: Social Media, Challenges | E10: Ílhavo | F10: Portugal | G10: 213.296 | H10: 43082 | I10: Seed | J10: 150 | K10: 100 | L10: Low | M10: =VLOOKUP(C10,Apoio!A:B,2,0) -> 11-50
A11: S&DG Consulting | B11: Seed | C11: 11-50 | D11: Energy Storage, Renewable | E11: Coimbra | F11: Portugal | G11: 245.591 | H11: 44194 | I11: Seed | J11: 100 | K11: 100 | L11: — | M11: =VLOOKUP(C11,Apoio!A:B,2,0) -> 11-50 | O11: Total | P11: =SUM(P2:P9) -> 181 | Q11: =SUM(Q2:Q9) -> 73
A12: BladeInsight | B12: Seed | C12: 11-50 | D12: Drone Mgmt, Renewable | E12: Porto S. | F12: Portugal | G12: 93.591 | H12: 44265 | I12: Seed | J12: €2,118,536 | K12: 129.139 | L12: Low | M12: =VLOOKUP(C12,Apoio!A:B,2,0) -> 11-50
A13: Digital Works | B13: Seed | C13: 11-50 | D13: Digital Media, Software | E13: Lisboa | F13: Portugal | G13: 498.852 | H13: 41445 | I13: Seed | J13: 150 | K13: 150 | L13: Low | M13: =VLOOKUP(C13,Apoio!A:B,2,0) -> 11-50
A14: Merytu | B14: Seed | C14: 11-50 | D14: Employment, Mobile Apps | E14: Lisboa | F14: Portugal | G14: 142.155 | H14: 44294 | I14: Seed | J14: 200 | K14: 200 | L14: Low | M14: =VLOOKUP(C14,Apoio!A:B,2,0) -> 11-50
A15: MagniFinance | B15: Seed | C15: 11-50 | D15: Fintech, Cashflow Mgmt | E15: Lisboa | F15: Portugal | G15: 633.519 | H15: 42064 | I15: Seed | J15: 200 | K15: 200 | L15: Low | M15: =VLOOKUP(C15,Apoio!A:B,2,0) -> 11-50 | O15: 11 - 500 | P15: =SUM(P2:P5) -> 145 | Q15: =SUM(Q2:Q5) -> 67
A16: PLUX biosignals | B16: Seed | C16: 11-50 | D16: Medical Device, Wireless | E16: Arruda V. | F16: Portugal | G16: 535.279 | H16: 41548 | I16: Seed | J16: 730 | K16: 230 | L16: Low | M16: =VLOOKUP(C16,Apoio!A:B,2,0) -> 11-50
A17: Mission To Escape | B17: Seed | C17: 11-50 | D17: Casual Games, Ent. | E17: Lisboa | F17: Portugal | G17: 184.569 | H17: 44985 | I17: Seed | J17: 250 | K17: 250 | L17: Low | M17: =VLOOKUP(C17,Apoio!A:B,2,0) -> 11-50
A18: Streambolico | B18: Seed | C18: 11-50 | D18: Video Streaming, Wireless | E18: Porto | F18: Portugal | G18: 3,671,559 | H18: 42339 | I18: M&A | J18: €1,250,000 | K18: 250 | L18: — | M18: =VLOOKUP(C18,Apoio!A:B,2,0) -> 11-50
A19: Dig. Manager Guru | B19: Seed | C19: 11-50 | D19: Sales Mgmt, Retail Tech | E19: Santarém | F19: Portugal | G19: 140.658 | H19: 43524 | I19: Seed | J19: 300 | K19: 300 | L19: Low | M19: =VLOOKUP(C19,Apoio!A:B,2,0) -> 11-50
A20: GFoundry | B20: Seed | C20: 11-50 | D20: HR Tech, Gamification | E20: Matosinhos | F20: Portugal | G20: 416.447 | H20: 41820 | I20: Seed | J20: 300 | K20: 300 | L20: Low | M20: =VLOOKUP(C20,Apoio!A:B,2,0) -> 11-50
A21: GrowIN Portugal | B21: Seed | C21: 11-50 | D21: Fintech, SaaS, Legal Tech | E21: Faro | F21: Portugal | G21: 168.628 | H21: 43415 | I21: Seed | J21: 450 | K21: 450 | L21: Low | M21: =VLOOKUP(C21,Apoio!A:B,2,0) -> 11-50
A22: Sled | B22: Seed | C22: 11-50 | D22: FinTech, Payments | E22: Curitiba | F22: Brasil | G22: 102.173 | H22: 44596 | I22: Seed | J22: R$7,500,000 | K22: 500 | L22: Low | M22: =VLOOKUP(C22,Apoio!A:B,2,0) -> 11-50
A23: BioMimetx | B23: Seed | C23: 501-1000 | D23: Biotech, Biofuel | E23: Coimbra | F23: Portugal | G23: 116.484 | H23: 44918 | I23: Seed | J23: €3,700,000 | K23: 500 | L23: Low | M23: =VLOOKUP(C23,Apoio!A:B,2,0) -> 501-1000
A24: Infinite Foundry | B24: Seed | C24: 11-50 | D24: 3D, Industrial VR | E24: Porto | F24: Portugal | G24: 120.094 | H24: 43451 | I24: Seed | J24: 500 | K24: 500 | L24: Low | M24: =VLOOKUP(C24,Apoio!A:B,2,0) -> 11-50
A25: X-Plora | B25: Seed | C25: 11-50 | D25: AR, XR, Tourism Tech | E25: Porto | F25: Portugal | G25: 151.616 | H25: 43731 | I25: Seed | J25: 500 | K25: 500 | L25: Low | M25: =VLOOKUP(C25,Apoio!A:B,2,0) -> 11-50
A26: Logical Safety | B26: Seed | C26: 11-50 | D26: IoT Safety, Predictive | E26: Leiria | F26: Portugal | G26: 217.882 | H26: 43501 | I26: Seed | J26: 500 | K26: 500 | L26: — | M26: =VLOOKUP(C26,Apoio!A:B,2,0) -> 11-50
A27: beamian | B27: Seed | C27: 11-50 | D27: Event Tech, IoT, NFC | E27: Porto | F27: Portugal | G27: 133.518 | H27: 43646 | I27: Seed | J27: 800 | K27: 600 | L27: Low | M27: =VLOOKUP(C27,Apoio!A:B,2,0) -> 11-50
A28: Bitcliq | B28: Seed | C28: 11-50 | D28: Blockchain, IoT, Fishing | E28: Caldas R. | F28: Portugal | G28: 151.726 | H28: 43504 | I28: Seed | J28: 600 | K28: 600 | L28: Low | M28: =VLOOKUP(C28,Apoio!A:B,2,0) -> 11-50
A29: B-PARTS.com | B29: Seed | C29: 11-50 | D29: Automotive E-Comm | E29: Porto | F29: Portugal | G29: 314.538 | H29: 41830 | I29: M&A | J29: 650 | K29: 650 | L29: Low | M29: =VLOOKUP(C29,Apoio!A:B,2,0) -> 11-50
A30: InKlusion | B30: Seed | C30: 11-50 | D30: Software, 3D Design | E30: Covilhã | F30: Portugal | G30: 168.544 | H30: 44864 | I30: Seed | J30: 700 | K30: 700 | L30: Low | M30: =VLOOKUP(C30,Apoio!A:B,2,0) -> 11-50
A31: Whizztek | B31: Seed | C31: 11-50 | D31: Sports Social Network | E31: Porto | F31: Portugal | G31: 1,142,007 | H31: 41817 | I31: Seed | J31: 750 | K31: 750 | L31: — | M31: =VLOOKUP(C31,Apoio!A:B,2,0) -> 11-50
A32: Treat U | B32: Seed | C32: 11-50 | D32: Biotech, Nanotech | E32: Leiria | F32: Portugal | G32: 3,070,907 | H32: 41480 | I32: M&A | J32: 760 | K32: 760 | L32: — | M32: =VLOOKUP(C32,Apoio!A:B,2,0) -> 11-50
A33: SocialTalk | B33: Seed | C33: 11-50 | D33: Influencer Marketing | E33: Lisboa | F33: Portugal | G33: 109.458 | H33: 44797 | I33: Seed | J33: 770 | K33: 770 | L33: Low | M33: =VLOOKUP(C33,Apoio!A:B,2,0) -> 11-50
A34: DocDigitizer | B34: Seed | C34: 11-50 | D34: Cognitive AI, SaaS | E34: Lisboa | F34: Portugal | G34: 97.413 | H34: 44454 | I34: Seed | J34: €1,190,000 | K34: 800 | L34: Low | M34: =VLOOKUP(C34,Apoio!A:B,2,0) -> 11-50
A35: Codavel | B35: Seed | C35: 11-50 | D35: App Performance, CDN | E35: Porto | F35: Portugal | G35: 127.886 | H35: 44470 | I35: Seed | J35: €2,900,000 | K35: 900 | L35: Low | M35: =VLOOKUP(C35,Apoio!A:B,2,0) -> 11-50
A36: ChemiTek | B36: Seed | C36: 11-50 | D36: Solar Panel Maintenance | E36: Esposende | F36: Portugal | G36: — | H36: — | I36: — | J36: — | K36: — | L36: — | M36: =VLOOKUP(C36,Apoio!A:B,2,0) -> 11-50
A37: Sabesp | B37: Post-IPO Debt | C37: 10001+ | D37: Sanitation | E37: São Paulo | F37: Brasil | G37: 49319 | H37: 46049 | I37: IPO | J37: $2.5B | K37: $ 1.5B | L37: Low | M37: =VLOOKUP(C37,Apoio!A:B,2,0) -> 10k+
A38: Pitzi | B38: Series D | C38: 101-250 | D38: InsurTech | E38: Osasco | F38: Brasil | G38: 46204 | H38: 43773 | I38: Late Stage Venture | J38: $29.7M | K38: $ 10.3M | L38: Low | M38: =VLOOKUP(C38,Apoio!A:B,2,0) -> 101-250
A39: Delend | B39: Seed | C39: 51-100 | D39: FinTech, SaaS | E39: São Paulo | F39: Brasil | G39: 41566 | H39: 45379 | I39: Seed | J39: $20.1M | K39: $ 10M | L39: Medium | M39: =VLOOKUP(C39,Apoio!A:B,2,0) -> 51-100
A40: Dolado | B40: Series A | C40: 51-100 | D40: B2B, Marketplace | E40: São Paulo | F40: Brasil | G40: 42072 | H40: 44656 | I40: Early Stage Venture | J40: $12.2M | K40: $ 10M | L40: Low | M40: =VLOOKUP(C40,Apoio!A:B,2,0) -> 51-100
...

Sheet Dataset - Ajustado
A1: Organização | B1: Tipo de Finan. | C1: Indústrias (Resumo) | D1: Localização | E1: País | F1: Data Últ. Finan. | G1: Status | H1: Total Captado | I1: Último Aporte | J1: Growth | K1: Funcionários (linkedin) | L1: Faixa de vidas | M1: Fundação | N1: Site | O1: Remover | P1: Seguidores Linkedin | Q1: Tem IA?
A2: Jáchegou | B2: Seed | C2: Delivery, E-Commerce | D2: Porto | E2: Portugal | F2: 44896 | G2: Seed | H2: 162000 | I2: 54000 | J2: Low | L2: 11 - 50 | O2: x
A3: PharmAssistant | B3: Seed | C3: Health Tech, Hardware | D3: Lisboa | E3: Portugal | F3: 41877 | G3: Seed | H3: 54000 | I3: 54000 | J3: Low | L3: 11 - 50 | O3: x
A4: Bandora | B4: Venture | C4: AI, Smart Building | D4: Porto | E4: Portugal | F4: 45832 | G4: — | H4: 2306214 | I4: 108000 | J4: Low | K4: 31 | L4: 11 - 50 | M4: 2017 | N4: http://www.bandorasystems.com
A5: Wakaru | B5: Seed | C5: Cyber Security, Analytics | D5: Torres V. | E5: Portugal | F5: 44222 | G5: Seed | H5: 108000 | I5: 108000 | J5: Low | L5: 11 - 50 | O5: x
A6: Avenidas | B6: Venture | C6: Mobility, Transportation | D6: Lisboa | E6: Portugal | F6: 45027 | G6: — | H6: 108000 | I6: 108000 | J6: High | K6: 169 | L6: 101 - 250 | M6: 2016 | N6: http://www.avenidas.pt
A7: Ubiwhere | B7: Seed | C7: Smart Cities, Software | D7: Barrocas | E7: Portugal | F7: 43132 | G7: Seed | H7: 108000 | I7: 108000 | J7: Low | K7: 57 | L7: 51 - 100 | M7: 2007 | N7: http://www.ubiwhere.com
A8: AQVA MORE | B8: Seed | C8: Water Purification, Mfg | D8: Oeiras | E8: Portugal | F8: 44187 | G8: Seed | H8: 108000 | I8: 108000 | J8: Low | L8: 11 - 50 | O8: x
A9: Cuckuu | B9: Seed | C9: Social Alarm, Mobile Apps | D9: Lisboa | E9: Portugal | F9: 42706 | G9: Seed | H9: 1164772 | I9: 108000 | J9: — | L9: 11 - 50 | N9: https://cuckuu.com | O9: x
A10: YouClap | B10: Seed | C10: Social Media, Challenges | D10: Ílhavo | E10: Portugal | F10: 43082 | G10: Seed | H10: 162000 | I10: 108000 | J10: Low | L10: 11 - 50 | O10: x
A11: S&DG Consulting | B11: Seed | C11: Energy Storage, Renewable | D11: Coimbra | E11: Portugal | F11: 44194 | G11: Seed | H11: 108000 | I11: 108000 | J11: — | L11: 11 - 50 | O11: x
A12: BladeInsight | B12: Seed | C12: Drone Mgmt, Renewable | D12: Porto S. | E12: Portugal | F12: 44265 | G12: Seed | H12: 2288019 | I12: 139471 | J12: Low | L12: 11 - 50 | N12: http://www.bladeinsight.com | O12: x
A13: Digital Works | B13: Seed | C13: Digital Media, Software | D13: Lisboa | E13: Portugal | F13: 41445 | G13: Seed | H13: 162000 | I13: 162000 | J13: Low | L13: 11 - 50 | M13: 2021 | N13: https://digitalworkssolution.com | O13: x
A14: Merytu | B14: Seed | C14: Employment, Mobile Apps | D14: Lisboa | E14: Portugal | F14: 44294 | G14: Seed | H14: 216000 | I14: 216000 | J14: Low | L14: 11 - 50 | M14: 2019 | N14: https://merytu.com/
A15: MagniFinance | B15: Seed | C15: Fintech, Cashflow Mgmt | D15: Lisboa | E15: Portugal | F15: 42064 | G15: Seed | H15: 216000 | I15: 216000 | J15: Low | L15: 11 - 50 | M15: 2015 | N15: http://www.magnifinance.com
A16: PLUX biosignals | B16: Seed | C16: Medical Device, Wireless | D16: Arruda V. | E16: Portugal | F16: 41548 | G16: Seed | H16: 788400 | I16: 248400 | J16: Low | K16: 35 | L16: 11 - 50 | M16: 2007 | N16: http://www.pluxbiosignals.com
A17: Mission To Escape | B17: Seed | C17: Casual Games, Ent. | D17: Lisboa | E17: Portugal | F17: 44985 | G17: Seed | H17: 270000 | I17: 270000 | J17: Low | K17: 29 | L17: 11 - 50 | M17: 2015 | N17: http://www.missiontoescape.com | O17: x
A18: Streambolico | B18: Seed | C18: Video Streaming, Wireless | D18: Porto | E18: Portugal | F18: 42339 | G18: M&A | H18: 1350000 | I18: 270000 | J18: — | L18: 11 - 50 | O18: x
A19: Dig. Manager Guru | B19: Seed | C19: Sales Mgmt, Retail Tech | D19: Santarém | E19: Portugal | F19: 43524 | G19: Seed | H19: 324000 | I19: 324000 | J19: Low | K19: 47 | L19: 11 - 50 | M19: 2017 | N19: https://digitalmanager.guru
A20: GFoundry | B20: Seed | C20: HR Tech, Gamification | D20: Matosinhos | E20: Portugal | F20: 41820 | G20: Seed | H20: 324000 | I20: 324000 | J20: Low | K20: 4 | L20: 2 - 10 | M20: 2014 | N20: http://gfoundry.com
A21: GrowIN Portugal | B21: Seed | C21: Fintech, SaaS, Legal Tech | D21: Faro | E21: Portugal | F21: 43415 | G21: Seed | H21: 486000 | I21: 486000 | J21: Low | L21: 11 - 50 | M21: 2018 | N21: http://www.growinportugal.com | O21: x
A22: Sled | B22: Seed | C22: FinTech, Payments | D22: Curitiba | E22: Brasil | F22: 44596 | G22: Seed | H22: 1350000 | I22: 540000 | J22: Low | L22: 11 - 50 | O22: x
A23: BioMimetx | B23: Seed | C23: Biotech, Biofuel | D23: Coimbra | E23: Portugal | F23: 44918 | G23: Seed | H23: 3996000 | I23: 540000 | J23: Low | K23: 8 | L23: 2 - 10 | M23: 2013 | N23: https://www.biomimetx.com/
A24: Infinite Foundry | B24: Seed | C24: 3D, Industrial VR | D24: Porto | E24: Portugal | F24: 43451 | G24: Seed | H24: 540000 | I24: 540000 | J24: Low | K24: 35 | L24: 11 - 50 | M24: 2017 | N24: https://www.infinitefoundry.com/
A25: X-Plora | B25: Seed | C25: AR, XR, Tourism Tech | D25: Porto | E25: Portugal | F25: 43731 | G25: Seed | H25: 540000 | I25: 540000 | J25: Low | L25: 11 - 50 | O25: x
A26: Logical Safety | B26: Seed | C26: IoT Safety, Predictive | D26: Leiria | E26: Portugal | F26: 43501 | G26: Seed | H26: 540000 | I26: 540000 | J26: — | L26: 11 - 50 | O26: x
A27: beamian | B27: Seed | C27: Event Tech, IoT, NFC | D27: Porto | E27: Portugal | F27: 43646 | G27: Seed | H27: 864000 | I27: 648000 | J27: Low | L27: 11 - 50 | M27: 2019 | N27: http://beamian.com
A28: Bitcliq | B28: Seed | C28: Blockchain, IoT, Fishing | D28: Caldas R. | E28: Portugal | F28: 43504 | G28: Seed | H28: 648000 | I28: 648000 | J28: Low | L28: 11 - 50 | M28: 2013 | N28: http://www.bitcliq.com
A29: B-PARTS | B29: Seed | C29: Automotive E-Comm | D29: Porto | E29: Portugal | F29: 41830 | G29: M&A | H29: 702000 | I29: 702000 | J29: Low | K29: 70 | L29: 51 - 100 | M29: 2013 | N29: https://www.b-parts.com
A30: InKlusion | B30: Seed | C30: Software, 3D Design | D30: Covilhã | E30: Portugal | F30: 44864 | G30: Seed | H30: 756000 | I30: 756000 | J30: Low | L30: 11 - 50 | M30: 2013 | N30: https://inklusion.pt
A31: Whizztek | B31: Seed | C31: Sports Social Network | D31: Porto | E31: Portugal | F31: 41817 | G31: Seed | H31: 810000 | I31: 810000 | J31: — | L31: 11 - 50 | M31: 2012 | O31: x
A32: Treat U | B32: Seed | C32: Biotech, Nanotech | D32: Leiria | E32: Portugal | F32: 41480 | G32: M&A | H32: 820800 | I32: 820800 | J32: — | L32: 11 - 50 | O32: x
A33: SocialTalk | B33: Seed | C33: Influencer Marketing | D33: Lisboa | E33: Portugal | F33: 44797 | G33: Seed | H33: 831600 | I33: 831600 | J33: Low | L33: 11 - 50 | M33: 2021 | N33: https://socialtalk.io
A34: DocDigitizer | B34: Seed | C34: Cognitive AI, SaaS | D34: Lisboa | E34: Portugal | F34: 44454 | G34: Seed | H34: 1285200 | I34: 864000 | J34: Low | L34: 11 - 50 | M34: 2017 | N34: https://www.docdigitizer.com/
A35: Codavel | B35: Seed | C35: App Performance, CDN | D35: Porto | E35: Portugal | F35: 44470 | G35: Seed | H35: 3132000 | I35: 972000 | J35: Low | L35: 11 - 50 | M35: 2018 | N35: https://www.codavel.com/
A36: ChemiTek | B36: Seed | C36: Solar Panel Maintenance | D36: Esposende | E36: Portugal | F36: — | G36: — | H36: — | I36: — | J36: — | L36: 11 - 50 | O36: x
A37: Sabesp | B37: Post-IPO Debt | C37: Sanitation | D37: São Paulo | E37: Brasil | F37: 46049 | G37: IPO | H37: 2500000000 | I37: 1500000000 | J37: Low | L37: 10000 - + | O37: x
A38: Pitzi | B38: Series D | C38: InsurTech | D38: Osasco | E38: Brasil | F38: 43773 | G38: Late Stage Venture | H38: 29700000 | I38: 10300000 | J38: Low | K38: 177 | L38: 101 - 250 | M38: 2012 | N38: http://www.pitzi.com.br
A39: Delend | B39: Seed | C39: FinTech, SaaS | D39: São Paulo | E39: Brasil | F39: 45379 | G39: Seed | H39: 20100000 | I39: 10000000 | J39: Medium | L39: 51 - 100 | M39: 2023 | N39: https://www.delend.finance/
A40: Dolado | B40: Series A | C40: B2B, Marketplace | D40: São Paulo | E40: Brasil | F40: 44656 | G40: Early Stage Venture | H40: 12200000 | I40: 10000000 | J40: Low | K40: 68 | L40: 51 - 100 | M40: 2020 | N40: http://dolado.com.br
...

Sheet Dataset 
A1: Organização | B1: Tipo de Finan. | C1: Indústrias (Resumo) | D1: País | E1: Data Últ. Finan. | F1: Total Captado | G1: Último Aporte | H1: Funcionários (linkedin) | I1: Faixa de vidas | J1: Fundação | K1: Site | L1: Seguidores Linkedin | M1: Tem IA? | N1: Momentum (%captado/captado total) | O1: Faturamento estimado | P1: Score Deeptech | Q1: Score Cloud Native | R1: Score DevTools | S1: Score Analytics | T1: Score Growth Stack | U1: Modelo de negócio
A2: AIDigitalEngine | B2: Seed | C2: Generative AI, RPA, Software | D2: Portugal | E2: 45168 | F2: 103000 | G2: 65000 | H2: 10 | I2: 11 - 50 | J2: 2021 | K2: https://www.ai-digitalengine.com/ | N2: =G2/F2 -> 0.63106796 | P2: 0 | Q2: 1 | R2: 0 | S2: 0 | T2: 0 | U2: Unknown
A3: Bandora | B3: Venture | C3: AI, Smart Building | D3: Portugal | E3: 45832 | F3: 2306214 | G3: 108000 | H3: 31 | I3: 11 - 50 | J3: 2017 | K3: http://www.bandorasystems.com | N3: =G3/F3 -> 0.046829999 | P3: 1 | Q3: 0 | R3: 1 | S3: 0 | T3: 2 | U3: B2B
A4: Avenidas | B4: Venture | C4: Mobility, Transportation | D4: Portugal | E4: 45027 | F4: 108000 | G4: 108000 | H4: 169 | I4: 101 - 250 | J4: 2016 | K4: http://www.avenidas.pt | N4: =G4/F4 -> 1 | O4: 6000000 | P4: 0 | Q4: 1 | R4: 0 | S4: 0 | T4: 1 | U4: B2B2C
A5: Ubiwhere | B5: Seed | C5: Smart Cities, Software | D5: Portugal | E5: 43132 | F5: 108000 | G5: 108000 | H5: 57 | I5: 51 - 100 | J5: 2007 | K5: http://www.ubiwhere.com | N5: =G5/F5 -> 1 | O5: 2000000 | P5: 2 | Q5: 2 | R5: 1 | S5: 1 | T5: 1 | U5: B2B
A6: Trigger.Systems | B6: Seed | C6: Agriculture Tech | D6: Portugal | E6: 43753 | F6: 130000 | G6: 130000 | H6: 9 | I6: 2 - 10 | J6: 2017 | K6: https://trigger.systems/ | N6: =G6/F6 -> 1 | P6: 0 | Q6: 1 | R6: 1 | S6: 0 | T6: 1 | U6: B2B
A7: Merytu | B7: Seed | C7: Employment, Mobile Apps | D7: Portugal | E7: 44294 | F7: 216000 | G7: 216000 | H7: 34 | I7: 11 - 50 | J7: 2019 | K7: https://merytu.com/ | N7: =G7/F7 -> 1 | P7: 0 | Q7: 0 | R7: 0 | S7: 1 | T7: 1 | U7: B2C
A8: MagniFinance | B8: Seed | C8: Fintech, Cashflow Mgmt | D8: Portugal | E8: 42064 | F8: 216000 | G8: 216000 | H8: 5 | I8: 11 - 50 | J8: 2015 | K8: http://www.magnifinance.com | N8: =G8/F8 -> 1 | O8: 322000 | P8: 0 | Q8: 0 | R8: 0 | S8: 1 | T8: 6 | U8: B2B
A9: PLUX biosignals | B9: Seed | C9: Medical Device, Wireless | D9: Portugal | E9: 41548 | F9: 788400 | G9: 248400 | H9: 35 | I9: 11 - 50 | J9: 2007 | K9: http://www.pluxbiosignals.com | N9: =G9/F9 -> 0.31506849 | O9: 2948000 | P9: 0 | Q9: 0 | R9: 1 | S9: 1 | T9: 4 | U9: B2C
A10: GeoInovaAI | B10: Seed | C10: AgTech, Computer Vision | D10: Brasil | E10: 45667 | F10: 300000 | G10: 250000 | H10: 10 | I10: 2 - 10 | J10: 2024 | K10: https://geoinova.com.br/ | N10: =G10/F10 -> 0.83333333 | P10: 1 | Q10: 1 | R10: 1 | S10: 2 | T10: 1 | U10: B2B
A11: Akurateco | B11: Seed | C11: Payments, SaaS | D11: Portugal | E11: 45078 | F11: 406400 | G11: 300000 | H11: 61 | I11: 51 - 100 | J11: 2019 | K11: https://akurateco.com/ | N11: =G11/F11 -> 0.73818898 | P11: 1 | Q11: 5 | R11: 6 | S11: 0 | T11: 4 | U11: Unknown
A12: Dig. Manager Guru | B12: Seed | C12: Sales Mgmt, Retail Tech | D12: Portugal | E12: 43524 | F12: 324000 | G12: 324000 | H12: 47 | I12: 11 - 50 | J12: 2017 | K12: https://digitalmanager.guru | N12: =G12/F12 -> 1 | P12: 0 | Q12: 0 | R12: 0 | S12: 1 | T12: 3 | U12: B2B2C
A13: GFoundry | B13: Seed | C13: HR Tech, Gamification | D13: Portugal | E13: 41820 | F13: 324000 | G13: 324000 | H13: 4 | I13: 2 - 10 | J13: 2014 | K13: http://gfoundry.com | N13: =G13/F13 -> 1 | P13: 1 | Q13: 0 | R13: 1 | S13: 0 | T13: 1 | U13: B2B
A14: Pink App | B14: Seed | C14: Collaboration, SaaS | D14: Brasil | E14: 43831 | F14: 735093 | G14: 400000 | H14: 19 | I14: 11 - 50 | J14: 2019 | K14: https://www.pinkapp.com/ | N14: =G14/F14 -> 0.54414884 | P14: 0 | Q14: 1 | R14: 0 | S14: 2 | T14: 0 | U14: B2B
A15: BlueMetrics | B15: Venture | C15: AI, Data Analytics | D15: Brasil | E15: 46077 | F15: 1021880 | G15: 486000 | H15: 56 | I15: 51 - 100 | J15: 2016 | K15: https://www.bluemetrics.ai/ | N15: =G15/F15 -> 0.475594 | P15: 1 | Q15: 4 | R15: 4 | S15: 1 | T15: 3 | U15: B2B
A16: Mobmio | B16: Series A | C16: Mobile Marketing | D16: Portugal | E16: 45311 | F16: 500000 | G16: 500000 | H16: 10 | I16: 2 - 10 | J16: 2023 | K16: https://mobmio.com/ | N16: =G16/F16 -> 1 | P16: 0 | Q16: 1 | R16: 0 | S16: 0 | T16: 2 | U16: B2C
A17: BioMimetx | B17: Seed | C17: Biotech, Biofuel | D17: Portugal | E17: 44918 | F17: 3996000 | G17: 540000 | H17: 8 | I17: 2 - 10 | J17: 2013 | K17: https://www.biomimetx.com/ | N17: =G17/F17 -> 0.13513514 | P17: 1 | Q17: 0 | R17: 0 | S17: 0 | T17: 0 | U17: B2B
A18: Infinite Foundry | B18: Seed | C18: 3D, Industrial VR | D18: Portugal | E18: 43451 | F18: 540000 | G18: 540000 | H18: 35 | I18: 11 - 50 | J18: 2017 | K18: https://www.infinitefoundry.com/ | N18: =G18/F18 -> 1 | P18: 1 | Q18: 1 | R18: 0 | S18: 0 | T18: 0 | U18: B2B
A19: Novvo | B19: Seed | C19: Wellness, Consumer | D19: Brasil | E19: 45623 | F19: 576000 | G19: 576000 | H19: 22 | I19: 11 - 50 | J19: 2022 | K19: https://novvo.com.br/ | N19: =G19/F19 -> 1 | P19: 1 | Q19: 0 | R19: 0 | S19: 0 | T19: 3 | U19: B2C
A20: Monest | B20: Venture | C20: Asset Recovery | D20: Brasil | E20: 45708 | F20: 576000 | G20: 576000 | H20: 97 | I20: 51 - 100 | J20: 2017 | K20: https://monest.com.br/ | N20: =G20/F20 -> 1 | P20: 1 | Q20: 1 | R20: 1 | S20: 2 | T20: 2 | U20: B2B2C
A21: beamian | B21: Seed | C21: Event Tech, IoT, NFC | D21: Portugal | E21: 43646 | F21: 864000 | G21: 648000 | H21: 7 | I21: 2 - 10 | J21: 2019 | K21: http://beamian.com | N21: =G21/F21 -> 0.75 | P21: 0 | Q21: 0 | R21: 1 | S21: 1 | T21: 3 | U21: B2C
... A24: B-PARTS | B24: Seed | C24: Automotive E-Comm | D24: Portugal | E24: 41830 | F24: 702000 | G24: 702000 | H24: 70 | I24: 51 - 100 | J24: 2013 | K24: https://www.b-parts.com | N24: =G24/F24 -> 1 | P24: 0 | Q24: 1 | R24: 0 | S24: 3 | T24: 4 | U24: B2C
A25: VOLL | B25: Seed | C25: Business Travel | D25: Brasil | E25: 43993 | F25: 720000 | G25: 720000 | H25: 649 | I25: 501 - 1000 | J25: 2017 | K25: https://www.govoll.com/ | N25: =G25/F25 -> 1 | O25: 151000000 | P25: 0 | Q25: 3 | R25: 4 | S25: 2 | T25: 5 | U25: Unknown
A26: Stattus4 | B26: Seed | C26: CleanTech, Water | D26: Brasil | E26: 45413 | F26: 1524198 | G26: 727363 | H26: 31 | I26: 11 - 50 | J26: 2014 | K26: https://stattus4.com/ | N26: =G26/F26 -> 0.47721031 | P26: 1 | Q26: 0 | R26: 3 | S26: 0 | T26: 0 | U26: B2B
A27: NOMADX | B27: Seed | C27: Travel, Marketplace | D27: Portugal | E27: 43861 | F27: 1000000 | G27: 750000 | H27: 7 | I27: 2 - 10 | J27: 2017 | K27: http://nomadx.com/ | N27: =G27/F27 -> 0.75 | P27: 0 | Q27: 0 | R27: 0 | S27: 1 | T27: 1 | U27: B2C
A28: InKlusion | B28: Seed | C28: Software, 3D Design | D28: Portugal | E28: 44864 | F28: 756000 | G28: 756000 | H28: 5 | I28: 2 - 10 | J28: 2013 | K28: https://inklusion.pt | N28: =G28/F28 -> 1 | O28: 377000 | P28: 2 | Q28: 0 | R28: 1 | S28: 0 | T28: 0 | U28: B2B2C
A29: SocialTalk | B29: Seed | C29: Influencer Marketing | D29: Portugal | E29: 44797 | F29: 831600 | G29: 831600 | H29: 7 | I29: 2 - 10 | J29: 2021 | K29: https://socialtalk.io | N29: =G29/F29 -> 1 | P29: 1 | Q29: 0 | R29: 1 | S29: 0 | T29: 0 | U29: B2B
A30: DocDigitizer | B30: Seed | C30: Cognitive AI, SaaS | D30: Portugal | E30: 44454 | F30: 1285200 | G30: 864000 | H30: 15 | I30: 11 - 50 | J30: 2017 | K30: https://www.docdigitizer.com/ | N30: =G30/F30 -> 0.67226891 | O30: 2300000 | P30: 1 | Q30: 0 | R30: 0 | S30: 1 | T30: 2 | U30: B2B
A31: Polkastarter | B31: Seed | C31: Blockchain, DeFi, Crowdfunding | D31: Portugal | E31: 44091 | F31: 875000 | G31: 875000 | H31: 18 | I31: 11 - 50 | J31: 2020 | K31: https://pols.xyz/ | N31: =G31/F31 -> 1 | P31: 0 | Q31: 0 | R31: 0 | S31: 0 | T31: 0 | U31: Unknown
A32: Noodle | B32: Seed | C32: Banking, Credit | D32: Brasil | E32: 45558 | F32: 3960000 | G32: 900000 | H32: 11 | I32: 11 - 50 | J32: 2020 | K32: https://www.noodle.cx/ | N32: =G32/F32 -> 0.22727273 | P32: 1 | Q32: 1 | R32: 0 | S32: 0 | T32: 2 | U32: B2B
A33: Codavel | B33: Seed | C33: App Performance, CDN | D33: Portugal | E33: 44470 | F33: 3132000 | G33: 972000 | H33: 5 | I33: 2 - 10 | J33: 2018 | K33: https://www.codavel.com/ | N33: =G33/F33 -> 0.31034483 | P33: 1 | Q33: 1 | R33: 2 | S33: 0 | T33: 2 | U33: B2C
A34: Konsi | B34: Seed | C34: FinTech, Payroll Loans | D34: Brasil | E34: 45467 | F34: 1611770 | G34: 1000000 | H34: 178 | I34: 101 - 250 | J34: 2021 | K34: https://www.konsi.com.br/ | N34: =G34/F34 -> 0.62043592 | P34: 0 | Q34: 0 | R34: 0 | S34: 2 | T34: 5 | U34: B2B2C
A35: Beegol | B35: Venture | C35: AI, Telecom | D35: Brasil | E35: 45632 | F35: 5600000 | G35: 1000000 | H35: 60 | I35: 51 - 100 | J35: 2019 | K35: https://www.beegol.com/ | N35: =G35/F35 -> 0.17857143 | P35: 0 | Q35: 1 | R35: 1 | S35: 0 | T35: 0 | U35: Unknown
A36: Culttivo | B36: Series A | C36: AgTech, Coffee Credit | D36: Brasil | E36: 45981 | F36: 16547191 | G36: 1000000 | H36: 68 | I36: 51 - 100 | J36: 2020 | K36: http://www.culttivo.com | N36: =G36/F36 -> 0.060433218 | P36: 0 | Q36: 0 | R36: 0 | S36: 0 | T36: 3 | U36: B2B
A37: Fasqon | B37: Seed | C37: FinTech, Neobank, Web3 | D37: Portugal | E37: 45352 | F37: 1300000 | G37: 1000000 | H37: 9 | I37: 2 - 10 | J37: 2023 | K37: https://fasqon.com/ | N37: =G37/F37 -> 0.76923077 | P37: 0 | Q37: 0 | R37: 0 | S37: 0 | T37: 0 | U37: B2B2C
A38: Albato | B38: Seed | C38: No-code, Automation, SaaS | D38: Portugal | E38: 44197 | F38: 1000000 | G38: 1000000 | H38: 43 | I38: 11 - 50 | J38: 2019 | K38: https://albato.com/ | N38: =G38/F38 -> 1 | P38: 1 | Q38: 1 | R38: 1 | S38: 1 | T38: 5 | U38: B2B
A39: Codavel (2) | B39: Seed | C39: Video CDN, Application Perf | D39: Portugal | E39: 44501 | F39: 3298430 | G39: 1043455 | H39: 5 | I39: 2 - 10 | J39: 2018 | K39: https://www.codavel.com/ | N39: =G39/F39 -> 0.31634899 | P39: 1 | Q39: 1 | R39: 2 | S39: 0 | T39: 2 | U39: B2C
A40: Manie | B40: Seed | C40: Energy Mgmt, Consulting | D40: Portugal | E40: 45770 | F40: 1080000 | G40: 1080000 | H40: 26 | I40: 11 - 50 | J40: 2024 | K40: https://manie.pt/ | N40: =G40/F40 -> 1 | P40: 0 | Q40: 0 | R40: 0 | S40: 0 | T40: 0 | U40: Unknown
A41: Anybrain | B41: Venture | C41: AI, Data Processing | D41: Portugal | E41: 43920 | F41: 1080000 | G41: 1080000 | H41: 19 | I41: 11 - 50 | J41: 2015 | K41: https://anybrain.gg/ | N41: =G41/F41 -> 1 | P41: 1 | Q41: 0 | R41: 3 | S41: 0 | T41: 0 | U41: B2B
A42: Processware | B42: Seed | C42: IT Software | D42: Portugal | E42: 41844 | F42: 1080000 | G42: 1080000 | H42: 36 | I42: 11 - 50 | J42: 2009 | K42: https://www.processwaregroup.com/ | N42: =G42/F42 -> 1 | P42: 0 | Q42: 0 | R42: 1 | S42: 0 | T42: 1 | U42: B2B
...

Sheet Base Final
A1: Empresa | B1: País | C1: Site | D1: Fundação | E1: Setor | F1: Tipo de Financiamento | G1: Faixa de HC | H1: Funcionários | I1: Idade (anos) | J1: Total Captado (USD) | K1: Último Aporte | L1: Data Últ. Finan. | M1: Captação per HC | N1: Último Aporte per HC | O1: Intensidade Histórica (Total Captado/Anos de fundação) | P1: Momentum (%ult aporte/total captado) | Q1: N Tecnologias | R1: Score Deeptech | S1: Score Cloud Native | T1: Score DevTools | U1: Score Analytics | V1: Score Growth Stack | W1: Modelo de NegÃ³cio
A2: GFoundry | B2: Portugal | C2: http://gfoundry.com | D2: 2014 | E2: HR Tech, Gamification | F2: Seed | G2: =VLOOKUP(A2,'Dataset '!A:I,9,0) -> 2 - 10 | H2: 4 | I2: 11 | J2: 324000 | K2: 324000 | L2: =VLOOKUP($A2,'Dataset '!$A:$I,5,0) -> 41820 | M2: =J2/H2 -> 81000 | N2: =K2/H2 -> 81000 | O2: =J2/I2 -> 29454.545 | P2: =K2/J2 -> 1 | Q2: 17 | R2: 1 | S2: 0 | T2: 1 | U2: 0 | V2: 1 | W2: B2B
A3: BioMimetx | B3: Portugal | C3: https://www.biomimetx.com/ | D3: 2013 | E3: Biotech, Biofuel | F3: Seed | G3: =VLOOKUP(A3,'Dataset '!A:I,9,0) -> 2 - 10 | H3: 6 | I3: 12 | J3: 3996000 | K3: 540000 | L3: =VLOOKUP($A3,'Dataset '!$A:$I,5,0) -> 44918 | M3: =J3/H3 -> 666000 | N3: =K3/H3 -> 90000 | O3: =J3/I3 -> 333000 | P3: =K3/J3 -> 0.13513514 | Q3: 10 | R3: 1 | S3: 0 | T3: 0 | U3: 0 | V3: 0 | W3: B2B
A4: Bandora | B4: Portugal | C4: http://www.bandorasystems.com | D4: 2017 | E4: AI, Smart Building | F4: Venture | G4: =VLOOKUP($A4,'Dataset '!$A:$I,9,0) -> 11 - 50 | H4: 31 | I4: 8 | J4: 2306214 | K4: 108000 | L4: =VLOOKUP($A4,'Dataset '!$A:$I,5,0) -> 45832 | M4: =J4/H4 -> 74394 | N4: =K4/H4 -> 3483.871 | O4: =J4/I4 -> 288276.75 | P4: =K4/J4 -> 0.046829999 | Q4: 12 | R4: 1 | S4: 0 | T4: 1 | U4: 0 | V4: 2 | W4: B2B
A5: Merytu | B5: Portugal | C5: https://merytu.com/ | D5: 2019 | E5: Employment, Mobile Apps | F5: Seed | G5: =VLOOKUP(A5,'Dataset '!A:I,9,0) -> 11 - 50 | H5: 34 | I5: 6 | J5: 216000 | K5: 216000 | L5: =VLOOKUP($A5,'Dataset '!$A:$I,5,0) -> 44294 | M5: =J5/H5 -> 6352.9412 | N5: =K5/H5 -> 6352.9412 | O5: =J5/I5 -> 36000 | P5: =K5/J5 -> 1 | Q5: 17 | R5: 0 | S5: 0 | T5: 0 | U5: 1 | V5: 1 | W5: B2C
A6: MagniFinance | B6: Portugal | C6: http://www.magnifinance.com | D6: 2015 | E6: Fintech, Cashflow Mgmt | F6: Seed | G6: =VLOOKUP(A6,'Dataset '!A:I,9,0) -> 11 - 50 | H6: 5 | I6: 10 | J6: 216000 | K6: 216000 | L6: =VLOOKUP($A6,'Dataset '!$A:$I,5,0) -> 42064 | M6: =J6/H6 -> 43200 | N6: =K6/H6 -> 43200 | O6: =J6/I6 -> 21600 | P6: =K6/J6 -> 1 | Q6: 27 | R6: 0 | S6: 0 | T6: 0 | U6: 1 | V6: 6 | W6: B2B
A7: PLUX biosignals | B7: Portugal | C7: http://www.pluxbiosignals.com | D7: 2007 | E7: Medical Device, Wireless | F7: Seed | G7: =VLOOKUP(A7,'Dataset '!A:I,9,0) -> 11 - 50 | H7: 35 | I7: 18 | J7: 788400 | K7: 248400 | L7: =VLOOKUP($A7,'Dataset '!$A:$I,5,0) -> 41548 | M7: =J7/H7 -> 22525.714 | N7: =K7/H7 -> 7097.1429 | O7: =J7/I7 -> 43800 | P7: =K7/J7 -> 0.31506849 | Q7: 45 | R7: 0 | S7: 0 | T7: 1 | U7: 1 | V7: 4 | W7: B2C
A8: Dig. Manager Guru | B8: Portugal | C8: https://digitalmanager.guru | D8: 2017 | E8: Sales Mgmt, Retail Tech | F8: Seed | G8: =VLOOKUP(A8,'Dataset '!A:I,9,0) -> 11 - 50 | H8: 46 | I8: 8 | J8: 324000 | K8: 324000 | L8: =VLOOKUP($A8,'Dataset '!$A:$I,5,0) -> 43524 | M8: =J8/H8 -> 7043.4783 | N8: =K8/H8 -> 7043.4783 | O8: =J8/I8 -> 40500 | P8: =K8/J8 -> 1 | Q8: 23 | R8: 0 | S8: 0 | T8: 0 | U8: 1 | V8: 3 | W8: B2B2C
A9: Infinite Foundry | B9: Portugal | C9: https://www.infinitefoundry.com/ | D9: 2017 | E9: 3D, Industrial VR | F9: Seed | G9: =VLOOKUP(A9,'Dataset '!A:I,9,0) -> 11 - 50 | H9: 35 | I9: 8 | J9: 540000 | K9: 540000 | L9: =VLOOKUP($A9,'Dataset '!$A:$I,5,0) -> 43451 | M9: =J9/H9 -> 15428.571 | N9: =K9/H9 -> 15428.571 | O9: =J9/I9 -> 67500 | P9: =K9/J9 -> 1 | Q9: 17 | R9: 1 | S9: 1 | T9: 0 | U9: 0 | V9: 0 | W9: B2B
A10: beamian | B10: Portugal | C10: http://beamian.com | D10: 2019 | E10: Event Tech, IoT, NFC | F10: Seed | G10: =VLOOKUP(A10,'Dataset '!A:I,9,0) -> 2 - 10 | H10: 7 | I10: 6 | J10: 864000 | K10: 648000 | L10: =VLOOKUP($A10,'Dataset '!$A:$I,5,0) -> 43646 | M10: =J10/H10 -> 123428.57 | N10: =K10/H10 -> 92571.429 | O10: =J10/I10 -> 144000 | P10: =K10/J10 -> 0.75 | Q10: 25 | R10: 0 | S10: 0 | T10: 1 | U10: 1 | V10: 3 | W10: B2C
A11: Bitcliq | B11: Portugal | C11: http://www.bitcliq.com | D11: 2013 | E11: Blockchain, IoT, Fishing | F11: Seed | G11: =VLOOKUP(A11,'Dataset '!A:I,9,0) -> 2 - 10 | H11: 5 | I11: 12 | J11: 648000 | K11: 648000 | L11: =VLOOKUP($A11,'Dataset '!$A:$I,5,0) -> 43504 | M11: =J11/H11 -> 129600 | N11: =K11/H11 -> 129600 | O11: =J11/I11 -> 54000 | P11: =K11/J11 -> 1 | Q11: 15 | R11: 1 | S11: 0 | T11: 1 | U11: 1 | V11: 0 | W11: B2B2C
A12: InKlusion | B12: Portugal | C12: https://inklusion.pt | D12: 2013 | E12: Software, 3D Design | F12: Seed | G12: =VLOOKUP(A12,'Dataset '!A:I,9,0) -> 2 - 10 | H12: 5 | I12: 12 | J12: 756000 | K12: 756000 | L12: =VLOOKUP($A12,'Dataset '!$A:$I,5,0) -> 44864 | M12: =J12/H12 -> 151200 | N12: =K12/H12 -> 151200 | O12: =J12/I12 -> 63000 | P12: =K12/J12 -> 1 | Q12: 13 | R12: 2 | S12: 0 | T12: 1 | U12: 0 | V12: 0 | W12: B2B2C
A13: SocialTalk | B13: Portugal | C13: https://socialtalk.io | D13: 2021 | E13: Influencer Marketing | F13: Seed | G13: =VLOOKUP(A13,'Dataset '!A:I,9,0) -> 2 - 10 | H13: 7 | I13: 4 | J13: 831600 | K13: 831600 | L13: =VLOOKUP($A13,'Dataset '!$A:$I,5,0) -> 44797 | M13: =J13/H13 -> 118800 | N13: =K13/H13 -> 118800 | O13: =J13/I13 -> 207900 | P13: =K13/J13 -> 1 | Q13: 10 | R13: 1 | S13: 0 | T13: 1 | U13: 0 | V13: 0 | W13: B2B
A14: DocDigitizer | B14: Portugal | C14: https://www.docdigitizer.com/ | D14: 2017 | E14: Cognitive AI, SaaS | F14: Seed | G14: =VLOOKUP(A14,'Dataset '!A:I,9,0) -> 11 - 50 | H14: 15 | I14: 8 | J14: 1285200 | K14: 864000 | L14: =VLOOKUP($A14,'Dataset '!$A:$I,5,0) -> 44454 | M14: =J14/H14 -> 85680 | N14: =K14/H14 -> 57600 | O14: =J14/I14 -> 160650 | P14: =K14/J14 -> 0.67226891 | Q14: 21 | R14: 1 | S14: 0 | T14: 0 | U14: 1 | V14: 2 | W14: B2B
A15: Codavel | B15: Portugal | C15: https://www.codavel.com/ | D15: 2018 | E15: App Performance, CDN | F15: Seed | G15: =VLOOKUP(A15,'Dataset '!A:I,9,0) -> 2 - 10 | H15: 5 | I15: 7 | J15: 3132000 | K15: 972000 | L15: =VLOOKUP($A15,'Dataset '!$A:$I,5,0) -> 44470 | M15: =J15/H15 -> 626400 | N15: =K15/H15 -> 194400 | O15: =J15/I15 -> 447428.57 | P15: =K15/J15 -> 0.31034483 | Q15: 17 | R15: 1 | S15: 1 | T15: 2 | U15: 0 | V15: 2 | W15: B2C
A16: Aravita | B16: Brasil | C16: https://www.aravita.com/ | D16: 2022 | E16: AI, AgTech | F16: Seed | G16: =VLOOKUP(A16,'Dataset '!A:I,9,0) -> 11 - 50 | H16: 18 | I16: 3 | J16: 2500000 | K16: 2500000 | L16: =VLOOKUP($A16,'Dataset '!$A:$I,5,0) -> 45015 | M16: =J16/H16 -> 138888.89 | N16: =K16/H16 -> 138888.89 | O16: =J16/I16 -> 833333.33 | P16: =K16/J16 -> 1 | Q16: 15 | R16: 1 | S16: 1 | T16: 0 | U16: 0 | V16: 1 | W16: B2B
... A31: GeoInovaAI | B31: Brasil | C31: https://geoinova.com.br/ | D31: 2024 | E31: AgTech, Computer Vision | F31: Seed | G31: =VLOOKUP(A31,'Dataset '!A:I,9,0) -> 2 - 10 | H31: 10 | I31: 1 | J31: 300000 | K31: 250000 | L31: =VLOOKUP($A31,'Dataset '!$A:$I,5,0) -> 45667 | M31: =J31/H31 -> 30000 | N31: =K31/H31 -> 25000 | O31: =J31/I31 -> 300000 | P31: =K31/J31 -> 0.83333333 | Q31: 29 | R31: 1 | S31: 1 | T31: 1 | U31: 2 | V31: 1 | W31: B2B
A32: Cumbuca | B32: Brasil | C32: https://www.cumbuca.com/ | D32: 2021 | E32: FinTech, Payments | F32: Seed | G32: =VLOOKUP(A32,'Dataset '!A:I,9,0) -> 11 - 50 | H32: 49 | I32: 4 | J32: 3125000 | K32: 3000000 | L32: =VLOOKUP($A32,'Dataset '!$A:$I,5,0) -> 45162 | M32: 104166.67 | N32: =K32/H32 -> 61224.49 | O32: =J32/I32 -> 781250 | P32: =K32/J32 -> 0.96 | Q32: 27 | R32: 0 | S32: 2 | T32: 0 | U32: 5 | V32: 5 | W32: B2B
A33: pleez | B33: Portugal | C33: http://www.trypleez.com | D33: 2020 | E33: FoodTech, Data | F33: Venture | G33: =VLOOKUP(A33,'Dataset '!A:I,9,0) -> 11 - 50 | H33: 27 | I33: 5 | J33: 6970906 | K33: 3000000 | L33: =VLOOKUP($A33,'Dataset '!$A:$I,5,0) -> 45602 | M33: 232363.53 | N33: =K33/H33 -> 111111.11 | O33: =J33/I33 -> 1394181.2 | P33: =K33/J33 -> 0.43036013 | Q33: 14 | R33: 1 | S33: 0 | T33: 0 | U33: 1 | V33: 0 | W33: B2B2C
A34: Virtuleap | B34: Portugal | C34: http://www.virtuleap.com | D34: 2018 | E34: Health Tech, VR, Neuroscience | F34: Seed | G34: =VLOOKUP(A34,'Dataset '!A:I,9,0) -> 11 - 50 | H34: 30 | I34: 7 | J34: 4904500 | K34: 3300000 | L34: =VLOOKUP($A34,'Dataset '!$A:$I,5,0) -> 44927 | M34: 163483.33 | N34: =K34/H34 -> 110000 | O34: =J34/I34 -> 700642.86 | P34: =K34/J34 -> 0.67285146 | Q34: 12 | R34: 1 | S34: 0 | T34: 0 | U34: 1 | V34: 1 | W34: B2B
A35: Lumx | B35: Brasil | C35: https://lumx.io/ | D35: https://lumx.io/ | E35: Web3, Stablecoins | F35: Seed | G35: =VLOOKUP(A35,'Dataset '!A:I,9,0) -> 11 - 50 | H35: 42 | J35: 3400000 | K35: 3400000 | L35: =VLOOKUP($A35,'Dataset '!$A:$I,5,0) -> 45945 | M35: 113333.33 | N35: =K35/H35 -> 80952.381 | O35: =J35/I35 -> #DIV/0! | P35: =K35/J35 -> 1 | Q35: 19 | R35: 0 | S35: 1 | T35: 1 | U35: 0 | V35: 3 | W35: B2B
A36: Ethena | B36: Portugal | C36: https://ethena.fi/ | D36: 2023 | E36: Blockchain, DeFi | F36: Venture | G36: =VLOOKUP(A36,'Dataset '!A:I,9,0) -> 11 - 50 | H36: 15 | I36: 2 | J36: 206820000 | K36: 30000000 | L36: =VLOOKUP($A36,'Dataset '!$A:$I,5,0) -> 45931 | M36: 6894000.0 | N36: =K36/H36 -> 2000000 | O36: =J36/I36 -> 103410000 | P36: =K36/J36 -> 0.14505367 | Q36: 16 | R36: 1 | S36: 3 | T36: 1 | U36: 1 | V36: 0 | W36: B2B2C
A37: Zharta | B37: Portugal | C37: https://www.zharta.io/ | D37: 2021 | E37: NFT Lending, FinTech | F37: Seed | G37: =VLOOKUP(A37,'Dataset '!A:I,9,0) -> 11 - 50 | H37: 11 | I37: 4 | J37: 4300000 | K37: 4300000 | L37: =VLOOKUP($A37,'Dataset '!$A:$I,5,0) -> 44762 | M37: 143333.33 | N37: =K37/H37 -> 390909.09 | O37: =J37/I37 -> 1075000 | P37: =K37/J37 -> 1 | Q37: 13 | R37: 0 | S37: 1 | T37: 1 | U37: 1 | V37: 1 | W37: B2B2C
A38: Ruvo | B38: Brasil | C38: https://ruvo.com/pt | D38: 2026 | E38: Crypto, Global Acc | F38: Seed | G38: =VLOOKUP(A38,'Dataset '!A:I,9,0) -> 11 - 50 | H38: 25 | I38: -1 | J38: 5100000 | K38: 4600000 | L38: =VLOOKUP($A38,'Dataset '!$A:$I,5,0) -> 46056 | M38: 170000.0 | N38: =K38/H38 -> 184000 | O38: =J38/I38 -> -5100000 | P38: =K38/J38 -> 0.90196078 | Q38: 6 | R38: 0 | S38: 1 | T38: 0 | U38: 0 | V38: 0 | W38: Unknown
A39: Pink App | B39: Brasil | C39: https://www.pinkapp.com/ | D39: 2019 | E39: Collaboration, SaaS | F39: Seed | G39: =VLOOKUP(A39,'Dataset '!A:I,9,0) -> 11 - 50 | H39: 24 | I39: 6 | J39: 735093 | K39: 400000 | L39: =VLOOKUP($A39,'Dataset '!$A:$I,5,0) -> 43831 | M39: 24503.1 | N39: =K39/H39 -> 16666.667 | O39: =J39/I39 -> 122515.5 | P39: =K39/J39 -> 0.54414884 | Q39: 10 | R39: 0 | S39: 1 | T39: 0 | U39: 2 | V39: 0 | W39: B2B
A40: Magie | B40: Brasil | C40: https://magie.com.br/ | D40: 2023 | E40: WhatsApp Banking | F40: Seed | G40: =VLOOKUP(A40,'Dataset '!A:I,9,0) -> 11 - 50 | H40: 37 | I40: 2 | J40: 10116153 | K40: 5000000 | L40: =VLOOKUP($A40,'Dataset '!$A:$I,5,0) -> 46036 | M40: 337205.1 | N40: =K40/H40 -> 135135.14 | O40: =J40/I40 -> 5058076.5 | P40: =K40/J40 -> 0.49425903 | Q40: 12 | R40: 0 | S40: 0 | T40: 0 | U40: 1 | V40: 1 | W40: B2C
A41: Mobmio | B41: Portugal | C41: https://mobmio.com/ | D41: 2023 | E41: Mobile Marketing | F41: Series A | G41: =VLOOKUP(A41,'Dataset '!A:I,9,0) -> 2 - 10 | H41: 10 | I41: 2 | J41: 500000 | K41: 500000 | L41: =VLOOKUP($A41,'Dataset '!$A:$I,5,0) -> 45311 | M41: 16666.67 | N41: =K41/H41 -> 50000 | O41: =J41/I41 -> 250000 | P41: =K41/J41 -> 1 | Q41: 10 | R41: 0 | S41: 1 | T41: 0 | U41: 0 | V41: 2 | W41: B2C
A42: AIDigitalEngine | B42: Portugal | C42: https://www.ai-digitalengine.com/ | D42: 2021 | E42: Generative AI, RPA, Software | F42: Seed | G42: =VLOOKUP(A42,'Dataset '!A:I,9,0) -> 11 - 50 | H42: 1 | I42: 4 | J42: 103000 | K42: 65000 | L42: =VLOOKUP($A42,'Dataset '!$A:$I,5,0) -> 45168 | M42: 3433.33 | N42: =K42/H42 -> 65000 | O42: =J42/I42 -> 25750 | P42: =K42/J42 -> 0.63106796 | Q42: 6 | R42: 0 | S42: 1 | T42: 0 | U42: 0 | V42: 0 | W42: Unknown
A43: Didimo | B43: Portugal | C43: https://www.didimo.co/ | D43: 2016 | E43: 3D, AI, Avatars | F43: Series A | G43: =VLOOKUP(A43,'Dataset '!A:I,9,0) -> 11 - 50 | H43: 33 | I43: 9 | J43: 16048983 | K43: 7150000 | L43: =VLOOKUP($A43,'Dataset '!$A:$I,5,0) -> 44845 | M43: 534966.1 | N43: =K43/H43 -> 216666.67 | O43: =J43/I43 -> 1783220.3 | P43: =K43/J43 -> 0.4455111 | Q43: 15 | R43: 1 | S43: 1 | T43: 1 | U43: 0 | V43: 2 | W43: B2B2C
A44: Galaxies | B44: Brasil | C44: https://www.galaxies.com.br/ | D44: 2022 | E44: Synthetic Personas, AI | F44: Seed | G44: =VLOOKUP(A44,'Dataset '!A:I,9,0) -> 11 - 50 | H44: 51 | I44: 3 | J44: 1450000 | K44: 700000 | L44: =VLOOKUP($A44,'Dataset '!$A:$I,5,0) -> 45931 | M44: 48333.33 | N44: =K44/H44 -> 13725.49 | O44: =J44/I44 -> 483333.33 | P44: =K44/J44 -> 0.48275862 | Q44: 14 | R44: 0 | S44: 1 | T44: 0 | U44: 2 | V44: 2 | W44: B2C
A45: NOMADX | B45: Portugal | C45: http://nomadx.com/ | D45: 2017 | E45: Travel, Marketplace | F45: Seed | G45: =VLOOKUP(A45,'Dataset '!A:I,9,0) -> 2 - 10 | H45: 7 | I45: 8 | J45: 1000000 | K45: 750000 | L45: =VLOOKUP($A45,'Dataset '!$A:$I,5,0) -> 43861 | M45: 33333.33 | N45: =K45/H45 -> 107142.86 | O45: =J45/I45 -> 125000 | P45: =K45/J45 -> 0.75 | Q45: 12 | R45: 0 | S45: 0 | T45: 0 | U45: 1 | V45: 1 | W45: B2C
A46: Polkastarter | B46: Portugal | C46: https://pols.xyz/ | D46: 2020 | E46: Blockchain, DeFi, Crowdfunding | F46: Seed | G46: =VLOOKUP(A46,'Dataset '!A:I,9,0) -> 11 - 50 | H46: 30 | I46: 5 | J46: 875000 | K46: 875000 | L46: =VLOOKUP($A46,'Dataset '!$A:$I,5,0) -> 44091 | M46: 29166.67 | N46: =K46/H46 -> 29166.667 | O46: =J46/I46 -> 175000 | P46: =K46/J46 -> 1 | Q46: 0 | R46: 0 | S46: 0 | T46: 0 | U46: 0 | V46: 0 | W46: Unknown
A47: Telepatia | B47: Brasil | C47: https://www.telepatia.ai/pt-br | D47: 2025 | E47: Health Tech, AI | F47: Seed | G47: =VLOOKUP(A47,'Dataset '!A:I,9,0) -> 11 - 50 | H47: 39 | I47: 0 | J47: 9000000 | K47: 9000000 | L47: =VLOOKUP($A47,'Dataset '!$A:$I,5,0) -> 45940 | M47: 300000.0 | N47: =K47/H47 -> 230769.23 | O47: =J47/I47 -> #DIV/0! | P47: =K47/J47 -> 1 | Q47: 8 | R47: 0 | S47: 0 | T47: 0 | U47: 0 | V47: 1 | W47: Unknown
... A101: Avenia | B101: Brasil | C101: https://avenia.io/ | D101: 2023 | E101: Blockchain, FX | F101: Series A | G101: =VLOOKUP(A101,'Dataset '!A:I,9,0) -> 11 - 50 | H101: 26 | I101: 2 | J101: 18900000 | K101: 16200000 | L101: =VLOOKUP($A101,'Dataset '!$A:$I,5,0) -> 46062 | M101: 630000.0 | N101: =K101/H101 -> 623076.92 | O101: =J101/I101 -> 9450000 | P101: =K101/J101 -> 0.85714286 | Q101: 11 | R101: 1 | S101: 0 | T101: 1 | U101: 0 | V101: 0 | W101: B2B
A102: Ubiwhere | B102: Portugal | C102: http://www.ubiwhere.com | D102: 2007 | E102: Smart Cities, Software | F102: Seed | G102: =VLOOKUP(A102,'Dataset '!A:I,9,0) -> 51 - 100 | H102: 57 | I102: 18 | J102: 108000 | K102: 108000 | L102: =VLOOKUP($A102,'Dataset '!$A:$I,5,0) -> 43132 | M102: =J102/H102 -> 1894.7368 | N102: =K102/H102 -> 1894.7368 | O102: =J102/I102 -> 6000 | P102: =K102/J102 -> 1 | Q102: 20 | R102: 2 | S102: 2 | T102: 1 | U102: 1 | V102: 1 | W102: B2B
A103: B-PARTS | B103: Portugal | C103: https://www.b-parts.com | D103: 2013 | E103: Automotive E-Comm | F103: Seed | G103: =VLOOKUP(A103,'Dataset '!A:I,9,0) -> 51 - 100 | H103: 70 | I103: 12 | J103: 702000 | K103: 702000 | L103: =VLOOKUP($A103,'Dataset '!$A:$I,5,0) -> 41830 | M103: =J103/H103 -> 10028.571 | N103: =K103/H103 -> 10028.571 | O103: =J103/I103 -> 58500 | P103: =K103/J103 -> 1 | Q103: 26 | R103: 0 | S103: 1 | T103: 0 | U103: 3 | V103: 4 | W103: B2C
A104: Delend | B104: Brasil | C104: https://www.delend.finance/ | D104: 2023 | E104: FinTech, SaaS | F104: Seed | G104: =VLOOKUP(A104,'Dataset '!A:I,9,0) -> 11 - 50 | H104: 18 | I104: 2 | J104: 20100000 | K104: 10000000 | L104: =VLOOKUP($A104,'Dataset '!$A:$I,5,0) -> 45379 | M104: =J104/H104 -> 1116666.7 | N104: =K104/H104 -> 555555.56 | O104: =J104/I104 -> 10050000 | P104: =K104/J104 -> 0.49751244 | Q104: 10 | R104: 1 | S104: 1 | T104: 0 | U104: 0 | V104: 0 | W104: B2B
A105: Dolado | B105: Brasil | C105: http://dolado.com.br | D105: 2020 | E105: B2B, Marketplace | F105: Series A | G105: =VLOOKUP(A105,'Dataset '!A:I,9,0) -> 51 - 100 | H105: 75 | I105: 5 | J105: 12200000 | K105: 10000000 | L105: =VLOOKUP($A105,'Dataset '!$A:$I,5,0) -> 44656 | M105: =J105/H105 -> 162666.67 | N105: =K105/H105 -> 133333.33 | O105: =J105/I105 -> 2440000 | P105: =K105/J105 -> 0.81967213 | Q105: 4 | R105: 0 | S105: 0 | T105: 0 | U105: 0 | V105: 0 | W105: B2B2C
A106: Visio.ai | B106: Brasil | C106: https://www.visio.ai/ | D106: 2021 | E106: AI, Comp. Vision | F106: Seed | G106: =VLOOKUP(A106,'Dataset '!A:I,9,0) -> 51 - 100 | H106: 67 | I106: 4 | J106: 2500000 | K106: 2500000 | L106: =VLOOKUP($A106,'Dataset '!$A:$I,5,0) -> 45363 | M106: =J106/H106 -> 37313.433 | N106: =K106/H106 -> 37313.433 | O106: =J106/I106 -> 625000 | P106: =K106/J106 -> 1 | Q106: 16 | R106: 1 | S106: 1 | T106: 0 | U106: 0 | V106: 2 | W106: B2B
A107: Destaxa | B107: Brasil | C107: https://destaxa.com.br/ | D107: 2021 | E107: FinTech, Payments | F107: Seed | G107: =VLOOKUP(A107,'Dataset '!A:I,9,0) -> 51 - 100 | H107: 36 | I107: 4 | J107: 10300000 | K107: 6000000 | L107: =VLOOKUP($A107,'Dataset '!$A:$I,5,0) -> 45254 | M107: =J107/H107 -> 286111.11 | N107: =K107/H107 -> 166666.67 | O107: =J107/I107 -> 2575000 | P107: =K107/J107 -> 0.58252427 | Q107: 11 | R107: 0 | S107: 0 | T107: 1 | U107: 0 | V107: 1 | W107: B2B2C
...

Sheet Definições
A1: Deeptech — tecnologias de alto conteúdo científico ou técnico: AI, IoT, Blockchain, Computer Vision, NLP, Biotech, Quantum. Um score alto aqui sinaliza que a empresa tem produto de maior complexidade técnica e barreira de entrada.
A3: Cloud Native — infraestrutura moderna: Kubernetes, Docker, Terraform, AWS, Prometheus, Snowflake. Sinaliza maturidade de engenharia e capacidade de escalar. Empresas em estágio inicial tendem a ter score baixo aqui.
A5: DevTools — linguagens e ferramentas de desenvolvimento: Python, React, Node.js, PostgreSQL, Git, GitLab. Sinaliza o tamanho e sofisticação do time de produto.
A7: Analytics — ferramentas de dados e monitoramento: Mixpanel, Datadog, Google Analytics, Amplitude, PowerBI. Sinaliza cultura data-driven — empresas que medem o que fazem.
A9: Growth Stack — ferramentas de vendas e marketing: HubSpot, Salesforce, Braze, Zendesk, LinkedIn Ads. Sinaliza que a empresa já está em modo de crescimento comercial ativo.

Sheet Critérios
A1: Startups | C1: Deeptech — tecnologias de alto conteúdo científico ou técnico: AI, IoT, Blockchain, Computer Vision, NLP, Biotech, Quantum. Um score alto aqui sinaliza que a empresa tem produto de maior complexidade técnica e barreira de entrada.
A2: Ativas
A3: Com pelo menos uma rodada de investimento conhecida | C3: Cloud Native — infraestrutura moderna: Kubernetes, Docker, Terraform, AWS, Prometheus, Snowflake. Sinaliza maturidade de engenharia e capacidade de escalar. Empresas em estágio inicial tendem a ter score baixo aqui.
A4: Não realizaram IPO
C5: DevTools — linguagens e ferramentas de desenvolvimento: Python, React, Node.js, PostgreSQL, Git, GitLab. Sinaliza o tamanho e sofisticação do time de produto.
C7: Analytics — ferramentas de dados e monitoramento: Mixpanel, Datadog, Google Analytics, Amplitude, PowerBI. Sinaliza cultura data-driven — empresas que medem o que fazem.
C9: Growth Stack — ferramentas de vendas e marketing: HubSpot, Salesforce, Braze, Zendesk, LinkedIn Ads. Sinaliza que a empresa já está em modo de crescimento comercial ativo.

Sheet Apoio
A1: Faixa
A2: 251-500 | B2: 251-500
A3: 11-50 | B3: 11-50
A4: 51-100 | B4: 51-100
A5: 5k-10k | B5: 5k-10k
A6: 1k-5k | B6: 1k-5k
A7: 10k+ | B7: 10k+
A8: 501-1000 | B8: 501-1000
A9: 101-250 | B9: 101-250
A10: 501-1k | B10: 501-1000
A11: 1001-5000 | B11: 1k-5k
A12: 10001+ | B12: 10k+
A13: 1001-5k | B13: 1k-5k
A14: 5001-10k | B14: 5k-10k
